2019-05-29 16:45:46,546 INFO: Microblog startup [in /home/arthur/Документы/microblog/app/__init__.py:43]
2019-05-29 16:45:58,985 ERROR: Exception on /editprofile [POST] [in /home/arthur/Документы/microblog/venv/lib/python3.6/site-packages/flask/app.py:1780]
Traceback (most recent call last):
  File "/home/arthur/Документы/microblog/venv/lib/python3.6/site-packages/sqlalchemy/engine/base.py", line 1244, in _execute_context
    cursor, statement, parameters, context
  File "/home/arthur/Документы/microblog/venv/lib/python3.6/site-packages/sqlalchemy/engine/default.py", line 552, in do_execute
    cursor.execute(statement, parameters)
sqlite3.IntegrityError: UNIQUE constraint failed: user.username

The above exception was the direct cause of the following exception:

Traceback (most recent call last):
  File "/home/arthur/Документы/microblog/venv/lib/python3.6/site-packages/flask/app.py", line 2311, in wsgi_app
    response = self.full_dispatch_request()
  File "/home/arthur/Документы/microblog/venv/lib/python3.6/site-packages/flask/app.py", line 1834, in full_dispatch_request
    rv = self.handle_user_exception(e)
  File "/home/arthur/Документы/microblog/venv/lib/python3.6/site-packages/flask/app.py", line 1737, in handle_user_exception
    reraise(exc_type, exc_value, tb)
  File "/home/arthur/Документы/microblog/venv/lib/python3.6/site-packages/flask/_compat.py", line 36, in reraise
    raise value
  File "/home/arthur/Документы/microblog/venv/lib/python3.6/site-packages/flask/app.py", line 1832, in full_dispatch_request
    rv = self.dispatch_request()
  File "/home/arthur/Документы/microblog/venv/lib/python3.6/site-packages/flask/app.py", line 1818, in dispatch_request
    return self.view_functions[rule.endpoint](**req.view_args)
  File "/home/arthur/Документы/microblog/venv/lib/python3.6/site-packages/flask_login/utils.py", line 261, in decorated_view
    return func(*args, **kwargs)
  File "/home/arthur/Документы/microblog/app/routes.py", line 92, in edit_profile
    db.session.commit()
  File "/home/arthur/Документы/microblog/venv/lib/python3.6/site-packages/sqlalchemy/orm/scoping.py", line 162, in do
    return getattr(self.registry(), name)(*args, **kwargs)
  File "/home/arthur/Документы/microblog/venv/lib/python3.6/site-packages/sqlalchemy/orm/session.py", line 1026, in commit
    self.transaction.commit()
  File "/home/arthur/Документы/microblog/venv/lib/python3.6/site-packages/sqlalchemy/orm/session.py", line 493, in commit
    self._prepare_impl()
  File "/home/arthur/Документы/microblog/venv/lib/python3.6/site-packages/sqlalchemy/orm/session.py", line 472, in _prepare_impl
    self.session.flush()
  File "/home/arthur/Документы/microblog/venv/lib/python3.6/site-packages/sqlalchemy/orm/session.py", line 2451, in flush
    self._flush(objects)
  File "/home/arthur/Документы/microblog/venv/lib/python3.6/site-packages/sqlalchemy/orm/session.py", line 2589, in _flush
    transaction.rollback(_capture_exception=True)
  File "/home/arthur/Документы/microblog/venv/lib/python3.6/site-packages/sqlalchemy/util/langhelpers.py", line 68, in __exit__
    compat.reraise(exc_type, exc_value, exc_tb)
  File "/home/arthur/Документы/microblog/venv/lib/python3.6/site-packages/sqlalchemy/util/compat.py", line 129, in reraise
    raise value
  File "/home/arthur/Документы/microblog/venv/lib/python3.6/site-packages/sqlalchemy/orm/session.py", line 2549, in _flush
    flush_context.execute()
  File "/home/arthur/Документы/microblog/venv/lib/python3.6/site-packages/sqlalchemy/orm/unitofwork.py", line 422, in execute
    rec.execute(self)
  File "/home/arthur/Документы/microblog/venv/lib/python3.6/site-packages/sqlalchemy/orm/unitofwork.py", line 589, in execute
    uow,
  File "/home/arthur/Документы/microblog/venv/lib/python3.6/site-packages/sqlalchemy/orm/persistence.py", line 236, in save_obj
    update,
  File "/home/arthur/Документы/microblog/venv/lib/python3.6/site-packages/sqlalchemy/orm/persistence.py", line 978, in _emit_update_statements
    statement, multiparams
  File "/home/arthur/Документы/microblog/venv/lib/python3.6/site-packages/sqlalchemy/engine/base.py", line 988, in execute
    return meth(self, multiparams, params)
  File "/home/arthur/Документы/microblog/venv/lib/python3.6/site-packages/sqlalchemy/sql/elements.py", line 287, in _execute_on_connection
    return connection._execute_clauseelement(self, multiparams, params)
  File "/home/arthur/Документы/microblog/venv/lib/python3.6/site-packages/sqlalchemy/engine/base.py", line 1107, in _execute_clauseelement
    distilled_params,
  File "/home/arthur/Документы/microblog/venv/lib/python3.6/site-packages/sqlalchemy/engine/base.py", line 1248, in _execute_context
    e, statement, parameters, cursor, context
  File "/home/arthur/Документы/microblog/venv/lib/python3.6/site-packages/sqlalchemy/engine/base.py", line 1466, in _handle_dbapi_exception
    util.raise_from_cause(sqlalchemy_exception, exc_info)
  File "/home/arthur/Документы/microblog/venv/lib/python3.6/site-packages/sqlalchemy/util/compat.py", line 383, in raise_from_cause
    reraise(type(exception), exception, tb=exc_tb, cause=cause)
  File "/home/arthur/Документы/microblog/venv/lib/python3.6/site-packages/sqlalchemy/util/compat.py", line 128, in reraise
    raise value.with_traceback(tb)
  File "/home/arthur/Документы/microblog/venv/lib/python3.6/site-packages/sqlalchemy/engine/base.py", line 1244, in _execute_context
    cursor, statement, parameters, context
  File "/home/arthur/Документы/microblog/venv/lib/python3.6/site-packages/sqlalchemy/engine/default.py", line 552, in do_execute
    cursor.execute(statement, parameters)
sqlalchemy.exc.IntegrityError: (sqlite3.IntegrityError) UNIQUE constraint failed: user.username
[SQL: UPDATE user SET username=?, about_me=? WHERE user.id = ?]
[parameters: ('petya', '', 3)]
(Background on this error at: http://sqlalche.me/e/gkpj)
2019-05-30 14:56:18,700 INFO: Microblog startup [in /home/arthur/Документы/microblog/app/__init__.py:43]
2019-05-30 14:59:26,073 INFO: Microblog startup [in /home/arthur/Документы/microblog/app/__init__.py:43]
2019-05-30 15:02:39,442 INFO: Microblog startup [in /home/arthur/Документы/microblog/app/__init__.py:43]
2019-05-30 15:02:59,989 INFO: Microblog startup [in /home/arthur/Документы/microblog/app/__init__.py:43]
2019-05-30 15:05:37,683 INFO: Microblog startup [in /home/arthur/Документы/microblog/app/__init__.py:43]
2019-05-30 15:05:51,011 INFO: Microblog startup [in /home/arthur/Документы/microblog/app/__init__.py:43]
2019-05-30 16:46:06,444 INFO: Microblog startup [in /home/arthur/Документы/microblog/app/__init__.py:43]
2019-05-30 16:48:00,932 INFO: Microblog startup [in /home/arthur/Документы/microblog/app/__init__.py:43]
2019-05-30 17:07:12,162 INFO: Microblog startup [in /home/arthur/Документы/microblog/app/__init__.py:43]
2019-05-30 17:07:37,496 INFO: Microblog startup [in /home/arthur/Документы/microblog/app/__init__.py:43]
2019-05-30 17:07:50,792 ERROR: Exception on /login [POST] [in /home/arthur/Документы/microblog/venv/lib/python3.6/site-packages/flask/app.py:1780]
Traceback (most recent call last):
  File "/home/arthur/Документы/microblog/venv/lib/python3.6/site-packages/flask/app.py", line 2311, in wsgi_app
    response = self.full_dispatch_request()
  File "/home/arthur/Документы/microblog/venv/lib/python3.6/site-packages/flask/app.py", line 1834, in full_dispatch_request
    rv = self.handle_user_exception(e)
  File "/home/arthur/Документы/microblog/venv/lib/python3.6/site-packages/flask/app.py", line 1737, in handle_user_exception
    reraise(exc_type, exc_value, tb)
  File "/home/arthur/Документы/microblog/venv/lib/python3.6/site-packages/flask/_compat.py", line 36, in reraise
    raise value
  File "/home/arthur/Документы/microblog/venv/lib/python3.6/site-packages/flask/app.py", line 1832, in full_dispatch_request
    rv = self.dispatch_request()
  File "/home/arthur/Документы/microblog/venv/lib/python3.6/site-packages/flask/app.py", line 1818, in dispatch_request
    return self.view_functions[rule.endpoint](**req.view_args)
  File "/home/arthur/Документы/microblog/app/routes.py", line 42, in login
    if not next_page or url_parse(next_page).netloc != '':
NameError: name 'url_parse' is not defined
