2019-06-03 13:10:14,207 ERROR: Exception on /explore [GET] [in /home/arthur/Документы/microblog/venv/lib/python3.6/site-packages/flask/app.py:1780]
Traceback (most recent call last):
  File "/home/arthur/Документы/microblog/venv/lib/python3.6/site-packages/flask/app.py", line 2311, in wsgi_app
    response = self.full_dispatch_request()
  File "/home/arthur/Документы/microblog/venv/lib/python3.6/site-packages/flask/app.py", line 1834, in full_dispatch_request
    rv = self.handle_user_exception(e)
  File "/home/arthur/Документы/microblog/venv/lib/python3.6/site-packages/flask/app.py", line 1737, in handle_user_exception
    reraise(exc_type, exc_value, tb)
  File "/home/arthur/Документы/microblog/venv/lib/python3.6/site-packages/flask/_compat.py", line 36, in reraise
    raise value
  File "/home/arthur/Документы/microblog/venv/lib/python3.6/site-packages/flask/app.py", line 1832, in full_dispatch_request
    rv = self.dispatch_request()
  File "/home/arthur/Документы/microblog/venv/lib/python3.6/site-packages/flask/app.py", line 1818, in dispatch_request
    return self.view_functions[rule.endpoint](**req.view_args)
  File "/home/arthur/Документы/microblog/venv/lib/python3.6/site-packages/flask_login/utils.py", line 261, in decorated_view
    return func(*args, **kwargs)
  File "/home/arthur/Документы/microblog/app/routes.py", line 130, in explore
    return render_template('index.html', title='Explore', posts=posts)
  File "/home/arthur/Документы/microblog/venv/lib/python3.6/site-packages/flask/templating.py", line 135, in render_template
    context, ctx.app)
  File "/home/arthur/Документы/microblog/venv/lib/python3.6/site-packages/flask/templating.py", line 117, in _render
    rv = template.render(context)
  File "/home/arthur/Документы/microblog/venv/lib/python3.6/site-packages/jinja2/asyncsupport.py", line 76, in render
    return original_render(self, *args, **kwargs)
  File "/home/arthur/Документы/microblog/venv/lib/python3.6/site-packages/jinja2/environment.py", line 1008, in render
    return self.environment.handle_exception(exc_info, True)
  File "/home/arthur/Документы/microblog/venv/lib/python3.6/site-packages/jinja2/environment.py", line 780, in handle_exception
    reraise(exc_type, exc_value, tb)
  File "/home/arthur/Документы/microblog/venv/lib/python3.6/site-packages/jinja2/_compat.py", line 37, in reraise
    raise value.with_traceback(tb)
  File "/home/arthur/Документы/microblog/app/templates/index.html", line 1, in top-level template code
    {% extends 'base.html' %}
  File "/home/arthur/Документы/microblog/app/templates/base.html", line 33, in top-level template code
    {% block content %}
  File "/home/arthur/Документы/microblog/app/templates/index.html", line 21, in block "content"
    {% include '_post.html' %}
  File "/home/arthur/Документы/microblog/app/templates/_post.html", line 3, in top-level template code
    <td><img src="{{ post.author.avatar(36) }}"></td>
jinja2.exceptions.UndefinedError: 'None' has no attribute 'avatar'
2019-06-03 13:10:36,267 ERROR: Exception on /explore [GET] [in /home/arthur/Документы/microblog/venv/lib/python3.6/site-packages/flask/app.py:1780]
Traceback (most recent call last):
  File "/home/arthur/Документы/microblog/venv/lib/python3.6/site-packages/flask/app.py", line 2311, in wsgi_app
    response = self.full_dispatch_request()
  File "/home/arthur/Документы/microblog/venv/lib/python3.6/site-packages/flask/app.py", line 1834, in full_dispatch_request
    rv = self.handle_user_exception(e)
  File "/home/arthur/Документы/microblog/venv/lib/python3.6/site-packages/flask/app.py", line 1737, in handle_user_exception
    reraise(exc_type, exc_value, tb)
  File "/home/arthur/Документы/microblog/venv/lib/python3.6/site-packages/flask/_compat.py", line 36, in reraise
    raise value
  File "/home/arthur/Документы/microblog/venv/lib/python3.6/site-packages/flask/app.py", line 1832, in full_dispatch_request
    rv = self.dispatch_request()
  File "/home/arthur/Документы/microblog/venv/lib/python3.6/site-packages/flask/app.py", line 1818, in dispatch_request
    return self.view_functions[rule.endpoint](**req.view_args)
  File "/home/arthur/Документы/microblog/venv/lib/python3.6/site-packages/flask_login/utils.py", line 261, in decorated_view
    return func(*args, **kwargs)
  File "/home/arthur/Документы/microblog/app/routes.py", line 130, in explore
    return render_template('index.html', title='Explore', posts=posts)
  File "/home/arthur/Документы/microblog/venv/lib/python3.6/site-packages/flask/templating.py", line 135, in render_template
    context, ctx.app)
  File "/home/arthur/Документы/microblog/venv/lib/python3.6/site-packages/flask/templating.py", line 117, in _render
    rv = template.render(context)
  File "/home/arthur/Документы/microblog/venv/lib/python3.6/site-packages/jinja2/asyncsupport.py", line 76, in render
    return original_render(self, *args, **kwargs)
  File "/home/arthur/Документы/microblog/venv/lib/python3.6/site-packages/jinja2/environment.py", line 1008, in render
    return self.environment.handle_exception(exc_info, True)
  File "/home/arthur/Документы/microblog/venv/lib/python3.6/site-packages/jinja2/environment.py", line 780, in handle_exception
    reraise(exc_type, exc_value, tb)
  File "/home/arthur/Документы/microblog/venv/lib/python3.6/site-packages/jinja2/_compat.py", line 37, in reraise
    raise value.with_traceback(tb)
  File "/home/arthur/Документы/microblog/app/templates/index.html", line 1, in top-level template code
    {% extends 'base.html' %}
  File "/home/arthur/Документы/microblog/app/templates/base.html", line 33, in top-level template code
    {% block content %}
  File "/home/arthur/Документы/microblog/app/templates/index.html", line 21, in block "content"
    {% include '_post.html' %}
  File "/home/arthur/Документы/microblog/app/templates/_post.html", line 3, in top-level template code
    <td><img src="{{ post.author.avatar(36) }}"></td>
jinja2.exceptions.UndefinedError: 'None' has no attribute 'avatar'
2019-06-03 13:10:38,980 ERROR: Exception on /explore [GET] [in /home/arthur/Документы/microblog/venv/lib/python3.6/site-packages/flask/app.py:1780]
Traceback (most recent call last):
  File "/home/arthur/Документы/microblog/venv/lib/python3.6/site-packages/flask/app.py", line 2311, in wsgi_app
    response = self.full_dispatch_request()
  File "/home/arthur/Документы/microblog/venv/lib/python3.6/site-packages/flask/app.py", line 1834, in full_dispatch_request
    rv = self.handle_user_exception(e)
  File "/home/arthur/Документы/microblog/venv/lib/python3.6/site-packages/flask/app.py", line 1737, in handle_user_exception
    reraise(exc_type, exc_value, tb)
  File "/home/arthur/Документы/microblog/venv/lib/python3.6/site-packages/flask/_compat.py", line 36, in reraise
    raise value
  File "/home/arthur/Документы/microblog/venv/lib/python3.6/site-packages/flask/app.py", line 1832, in full_dispatch_request
    rv = self.dispatch_request()
  File "/home/arthur/Документы/microblog/venv/lib/python3.6/site-packages/flask/app.py", line 1818, in dispatch_request
    return self.view_functions[rule.endpoint](**req.view_args)
  File "/home/arthur/Документы/microblog/venv/lib/python3.6/site-packages/flask_login/utils.py", line 261, in decorated_view
    return func(*args, **kwargs)
  File "/home/arthur/Документы/microblog/app/routes.py", line 130, in explore
    return render_template('index.html', title='Explore', posts=posts)
  File "/home/arthur/Документы/microblog/venv/lib/python3.6/site-packages/flask/templating.py", line 135, in render_template
    context, ctx.app)
  File "/home/arthur/Документы/microblog/venv/lib/python3.6/site-packages/flask/templating.py", line 117, in _render
    rv = template.render(context)
  File "/home/arthur/Документы/microblog/venv/lib/python3.6/site-packages/jinja2/asyncsupport.py", line 76, in render
    return original_render(self, *args, **kwargs)
  File "/home/arthur/Документы/microblog/venv/lib/python3.6/site-packages/jinja2/environment.py", line 1008, in render
    return self.environment.handle_exception(exc_info, True)
  File "/home/arthur/Документы/microblog/venv/lib/python3.6/site-packages/jinja2/environment.py", line 780, in handle_exception
    reraise(exc_type, exc_value, tb)
  File "/home/arthur/Документы/microblog/venv/lib/python3.6/site-packages/jinja2/_compat.py", line 37, in reraise
    raise value.with_traceback(tb)
  File "/home/arthur/Документы/microblog/app/templates/index.html", line 1, in top-level template code
    {% extends 'base.html' %}
  File "/home/arthur/Документы/microblog/app/templates/base.html", line 33, in top-level template code
    {% block content %}
  File "/home/arthur/Документы/microblog/app/templates/index.html", line 21, in block "content"
    {% include '_post.html' %}
  File "/home/arthur/Документы/microblog/app/templates/_post.html", line 3, in top-level template code
    <td><img src="{{ post.author.avatar(36) }}"></td>
jinja2.exceptions.UndefinedError: 'None' has no attribute 'avatar'
2019-06-03 13:14:23,017 INFO: Microblog startup [in /home/arthur/Документы/microblog/app/__init__.py:43]
